{
 "cells": [
  {
   "cell_type": "code",
   "execution_count": 1,
   "metadata": {},
   "outputs": [],
   "source": [
    "import pandas as pd\n",
    "import numpy as np\n",
    "import matplotlib.pyplot as plt"
   ]
  },
  {
   "cell_type": "code",
   "execution_count": 3,
   "metadata": {},
   "outputs": [
    {
     "name": "stdout",
     "output_type": "stream",
     "text": [
      "      age     sex     bmi  children smoker      charges\n",
      "0      19  female  27.900         0    yes  16884.92400\n",
      "1      18    male  33.770         1     no   1725.55230\n",
      "2      28    male  33.000         3     no   4449.46200\n",
      "3      33    male  22.705         0     no  21984.47061\n",
      "4      32    male  28.880         0     no   3866.85520\n",
      "...   ...     ...     ...       ...    ...          ...\n",
      "1333   50    male  30.970         3     no  10600.54830\n",
      "1334   18  female  31.920         0     no   2205.98080\n",
      "1335   18  female  36.850         0     no   1629.83350\n",
      "1336   21  female  25.800         0     no   2007.94500\n",
      "1337   61  female  29.070         0    yes  29141.36030\n",
      "\n",
      "[1338 rows x 6 columns]\n"
     ]
    }
   ],
   "source": [
    "Dataset=pd.read_csv(\"insurance_pre.csv\")\n",
    "print(Dataset)"
   ]
  },
  {
   "cell_type": "code",
   "execution_count": 4,
   "metadata": {},
   "outputs": [],
   "source": [
    "Dataset=pd.get_dummies(Dataset,dtype=int,drop_first=True)"
   ]
  },
  {
   "cell_type": "code",
   "execution_count": 5,
   "metadata": {},
   "outputs": [
    {
     "data": {
      "text/plain": [
       "Index(['age', 'bmi', 'children', 'charges', 'sex_male', 'smoker_yes'], dtype='object')"
      ]
     },
     "execution_count": 5,
     "metadata": {},
     "output_type": "execute_result"
    }
   ],
   "source": [
    "Dataset.columns"
   ]
  },
  {
   "cell_type": "code",
   "execution_count": 7,
   "metadata": {},
   "outputs": [],
   "source": [
    "Independent=Dataset[['age', 'bmi', 'children', 'sex_male', 'smoker_yes']]\n",
    "Dependent=Dataset[['charges']]"
   ]
  },
  {
   "cell_type": "code",
   "execution_count": 8,
   "metadata": {},
   "outputs": [],
   "source": [
    "from sklearn.model_selection import train_test_split\n",
    "X_train,X_test,Y_train,Y_test=train_test_split(Independent,Dependent,test_size=0.30,random_state=0)"
   ]
  },
  {
   "cell_type": "code",
   "execution_count": 9,
   "metadata": {},
   "outputs": [],
   "source": [
    "from sklearn.preprocessing import StandardScaler\n",
    "sc=StandardScaler()\n",
    "X_train=sc.fit_transform(X_train)\n",
    "X_test=sc.fit_transform(X_test)"
   ]
  },
  {
   "cell_type": "code",
   "execution_count": 19,
   "metadata": {},
   "outputs": [],
   "source": [
    "from sklearn.model_selection import GridSearchCV\n",
    "from sklearn.ensemble import RandomForestRegressor\n",
    "Param_grid= {'criterion':['mse','mae'],\n",
    "'max_features': ['auto','sqrt','log2'],\n",
    "'n_estimators':[10,100]}"
   ]
  },
  {
   "cell_type": "code",
   "execution_count": 26,
   "metadata": {},
   "outputs": [
    {
     "name": "stdout",
     "output_type": "stream",
     "text": [
      "Fitting 5 folds for each of 12 candidates, totalling 60 fits\n"
     ]
    },
    {
     "ename": "ValueError",
     "evalue": "\nAll the 60 fits failed.\nIt is very likely that your model is misconfigured.\nYou can try to debug the error by setting error_score='raise'.\n\nBelow are more details about the failures:\n--------------------------------------------------------------------------------\n4 fits failed with the following error:\nTraceback (most recent call last):\n  File \"c:\\Users\\Gajalakshmi G\\AppData\\Local\\Programs\\Python\\Python312\\Lib\\site-packages\\sklearn\\model_selection\\_validation.py\", line 895, in _fit_and_score\n    estimator.fit(X_train, y_train, **fit_params)\n  File \"c:\\Users\\Gajalakshmi G\\AppData\\Local\\Programs\\Python\\Python312\\Lib\\site-packages\\sklearn\\base.py\", line 1467, in wrapper\n    estimator._validate_params()\n  File \"c:\\Users\\Gajalakshmi G\\AppData\\Local\\Programs\\Python\\Python312\\Lib\\site-packages\\sklearn\\base.py\", line 666, in _validate_params\n    validate_parameter_constraints(\n  File \"c:\\Users\\Gajalakshmi G\\AppData\\Local\\Programs\\Python\\Python312\\Lib\\site-packages\\sklearn\\utils\\_param_validation.py\", line 95, in validate_parameter_constraints\n    raise InvalidParameterError(\nsklearn.utils._param_validation.InvalidParameterError: The 'criterion' parameter of RandomForestRegressor must be a str among {'squared_error', 'friedman_mse', 'poisson', 'absolute_error'}. Got 'mse' instead.\n\n--------------------------------------------------------------------------------\n4 fits failed with the following error:\nTraceback (most recent call last):\n  File \"c:\\Users\\Gajalakshmi G\\AppData\\Local\\Programs\\Python\\Python312\\Lib\\site-packages\\sklearn\\model_selection\\_validation.py\", line 895, in _fit_and_score\n    estimator.fit(X_train, y_train, **fit_params)\n  File \"c:\\Users\\Gajalakshmi G\\AppData\\Local\\Programs\\Python\\Python312\\Lib\\site-packages\\sklearn\\base.py\", line 1467, in wrapper\n    estimator._validate_params()\n  File \"c:\\Users\\Gajalakshmi G\\AppData\\Local\\Programs\\Python\\Python312\\Lib\\site-packages\\sklearn\\base.py\", line 666, in _validate_params\n    validate_parameter_constraints(\n  File \"c:\\Users\\Gajalakshmi G\\AppData\\Local\\Programs\\Python\\Python312\\Lib\\site-packages\\sklearn\\utils\\_param_validation.py\", line 95, in validate_parameter_constraints\n    raise InvalidParameterError(\nsklearn.utils._param_validation.InvalidParameterError: The 'criterion' parameter of RandomForestRegressor must be a str among {'squared_error', 'friedman_mse', 'absolute_error', 'poisson'}. Got 'mse' instead.\n\n--------------------------------------------------------------------------------\n4 fits failed with the following error:\nTraceback (most recent call last):\n  File \"c:\\Users\\Gajalakshmi G\\AppData\\Local\\Programs\\Python\\Python312\\Lib\\site-packages\\sklearn\\model_selection\\_validation.py\", line 895, in _fit_and_score\n    estimator.fit(X_train, y_train, **fit_params)\n  File \"c:\\Users\\Gajalakshmi G\\AppData\\Local\\Programs\\Python\\Python312\\Lib\\site-packages\\sklearn\\base.py\", line 1467, in wrapper\n    estimator._validate_params()\n  File \"c:\\Users\\Gajalakshmi G\\AppData\\Local\\Programs\\Python\\Python312\\Lib\\site-packages\\sklearn\\base.py\", line 666, in _validate_params\n    validate_parameter_constraints(\n  File \"c:\\Users\\Gajalakshmi G\\AppData\\Local\\Programs\\Python\\Python312\\Lib\\site-packages\\sklearn\\utils\\_param_validation.py\", line 95, in validate_parameter_constraints\n    raise InvalidParameterError(\nsklearn.utils._param_validation.InvalidParameterError: The 'criterion' parameter of RandomForestRegressor must be a str among {'absolute_error', 'squared_error', 'friedman_mse', 'poisson'}. Got 'mse' instead.\n\n--------------------------------------------------------------------------------\n4 fits failed with the following error:\nTraceback (most recent call last):\n  File \"c:\\Users\\Gajalakshmi G\\AppData\\Local\\Programs\\Python\\Python312\\Lib\\site-packages\\sklearn\\model_selection\\_validation.py\", line 895, in _fit_and_score\n    estimator.fit(X_train, y_train, **fit_params)\n  File \"c:\\Users\\Gajalakshmi G\\AppData\\Local\\Programs\\Python\\Python312\\Lib\\site-packages\\sklearn\\base.py\", line 1467, in wrapper\n    estimator._validate_params()\n  File \"c:\\Users\\Gajalakshmi G\\AppData\\Local\\Programs\\Python\\Python312\\Lib\\site-packages\\sklearn\\base.py\", line 666, in _validate_params\n    validate_parameter_constraints(\n  File \"c:\\Users\\Gajalakshmi G\\AppData\\Local\\Programs\\Python\\Python312\\Lib\\site-packages\\sklearn\\utils\\_param_validation.py\", line 95, in validate_parameter_constraints\n    raise InvalidParameterError(\nsklearn.utils._param_validation.InvalidParameterError: The 'criterion' parameter of RandomForestRegressor must be a str among {'squared_error', 'poisson', 'friedman_mse', 'absolute_error'}. Got 'mse' instead.\n\n--------------------------------------------------------------------------------\n4 fits failed with the following error:\nTraceback (most recent call last):\n  File \"c:\\Users\\Gajalakshmi G\\AppData\\Local\\Programs\\Python\\Python312\\Lib\\site-packages\\sklearn\\model_selection\\_validation.py\", line 895, in _fit_and_score\n    estimator.fit(X_train, y_train, **fit_params)\n  File \"c:\\Users\\Gajalakshmi G\\AppData\\Local\\Programs\\Python\\Python312\\Lib\\site-packages\\sklearn\\base.py\", line 1467, in wrapper\n    estimator._validate_params()\n  File \"c:\\Users\\Gajalakshmi G\\AppData\\Local\\Programs\\Python\\Python312\\Lib\\site-packages\\sklearn\\base.py\", line 666, in _validate_params\n    validate_parameter_constraints(\n  File \"c:\\Users\\Gajalakshmi G\\AppData\\Local\\Programs\\Python\\Python312\\Lib\\site-packages\\sklearn\\utils\\_param_validation.py\", line 95, in validate_parameter_constraints\n    raise InvalidParameterError(\nsklearn.utils._param_validation.InvalidParameterError: The 'criterion' parameter of RandomForestRegressor must be a str among {'squared_error', 'poisson', 'absolute_error', 'friedman_mse'}. Got 'mse' instead.\n\n--------------------------------------------------------------------------------\n4 fits failed with the following error:\nTraceback (most recent call last):\n  File \"c:\\Users\\Gajalakshmi G\\AppData\\Local\\Programs\\Python\\Python312\\Lib\\site-packages\\sklearn\\model_selection\\_validation.py\", line 895, in _fit_and_score\n    estimator.fit(X_train, y_train, **fit_params)\n  File \"c:\\Users\\Gajalakshmi G\\AppData\\Local\\Programs\\Python\\Python312\\Lib\\site-packages\\sklearn\\base.py\", line 1467, in wrapper\n    estimator._validate_params()\n  File \"c:\\Users\\Gajalakshmi G\\AppData\\Local\\Programs\\Python\\Python312\\Lib\\site-packages\\sklearn\\base.py\", line 666, in _validate_params\n    validate_parameter_constraints(\n  File \"c:\\Users\\Gajalakshmi G\\AppData\\Local\\Programs\\Python\\Python312\\Lib\\site-packages\\sklearn\\utils\\_param_validation.py\", line 95, in validate_parameter_constraints\n    raise InvalidParameterError(\nsklearn.utils._param_validation.InvalidParameterError: The 'criterion' parameter of RandomForestRegressor must be a str among {'poisson', 'squared_error', 'friedman_mse', 'absolute_error'}. Got 'mse' instead.\n\n--------------------------------------------------------------------------------\n4 fits failed with the following error:\nTraceback (most recent call last):\n  File \"c:\\Users\\Gajalakshmi G\\AppData\\Local\\Programs\\Python\\Python312\\Lib\\site-packages\\sklearn\\model_selection\\_validation.py\", line 895, in _fit_and_score\n    estimator.fit(X_train, y_train, **fit_params)\n  File \"c:\\Users\\Gajalakshmi G\\AppData\\Local\\Programs\\Python\\Python312\\Lib\\site-packages\\sklearn\\base.py\", line 1467, in wrapper\n    estimator._validate_params()\n  File \"c:\\Users\\Gajalakshmi G\\AppData\\Local\\Programs\\Python\\Python312\\Lib\\site-packages\\sklearn\\base.py\", line 666, in _validate_params\n    validate_parameter_constraints(\n  File \"c:\\Users\\Gajalakshmi G\\AppData\\Local\\Programs\\Python\\Python312\\Lib\\site-packages\\sklearn\\utils\\_param_validation.py\", line 95, in validate_parameter_constraints\n    raise InvalidParameterError(\nsklearn.utils._param_validation.InvalidParameterError: The 'criterion' parameter of RandomForestRegressor must be a str among {'poisson', 'absolute_error', 'squared_error', 'friedman_mse'}. Got 'mse' instead.\n\n--------------------------------------------------------------------------------\n2 fits failed with the following error:\nTraceback (most recent call last):\n  File \"c:\\Users\\Gajalakshmi G\\AppData\\Local\\Programs\\Python\\Python312\\Lib\\site-packages\\sklearn\\model_selection\\_validation.py\", line 895, in _fit_and_score\n    estimator.fit(X_train, y_train, **fit_params)\n  File \"c:\\Users\\Gajalakshmi G\\AppData\\Local\\Programs\\Python\\Python312\\Lib\\site-packages\\sklearn\\base.py\", line 1467, in wrapper\n    estimator._validate_params()\n  File \"c:\\Users\\Gajalakshmi G\\AppData\\Local\\Programs\\Python\\Python312\\Lib\\site-packages\\sklearn\\base.py\", line 666, in _validate_params\n    validate_parameter_constraints(\n  File \"c:\\Users\\Gajalakshmi G\\AppData\\Local\\Programs\\Python\\Python312\\Lib\\site-packages\\sklearn\\utils\\_param_validation.py\", line 95, in validate_parameter_constraints\n    raise InvalidParameterError(\nsklearn.utils._param_validation.InvalidParameterError: The 'criterion' parameter of RandomForestRegressor must be a str among {'poisson', 'absolute_error', 'friedman_mse', 'squared_error'}. Got 'mse' instead.\n\n--------------------------------------------------------------------------------\n5 fits failed with the following error:\nTraceback (most recent call last):\n  File \"c:\\Users\\Gajalakshmi G\\AppData\\Local\\Programs\\Python\\Python312\\Lib\\site-packages\\sklearn\\model_selection\\_validation.py\", line 895, in _fit_and_score\n    estimator.fit(X_train, y_train, **fit_params)\n  File \"c:\\Users\\Gajalakshmi G\\AppData\\Local\\Programs\\Python\\Python312\\Lib\\site-packages\\sklearn\\base.py\", line 1467, in wrapper\n    estimator._validate_params()\n  File \"c:\\Users\\Gajalakshmi G\\AppData\\Local\\Programs\\Python\\Python312\\Lib\\site-packages\\sklearn\\base.py\", line 666, in _validate_params\n    validate_parameter_constraints(\n  File \"c:\\Users\\Gajalakshmi G\\AppData\\Local\\Programs\\Python\\Python312\\Lib\\site-packages\\sklearn\\utils\\_param_validation.py\", line 95, in validate_parameter_constraints\n    raise InvalidParameterError(\nsklearn.utils._param_validation.InvalidParameterError: The 'criterion' parameter of RandomForestRegressor must be a str among {'poisson', 'absolute_error', 'friedman_mse', 'squared_error'}. Got 'mae' instead.\n\n--------------------------------------------------------------------------------\n4 fits failed with the following error:\nTraceback (most recent call last):\n  File \"c:\\Users\\Gajalakshmi G\\AppData\\Local\\Programs\\Python\\Python312\\Lib\\site-packages\\sklearn\\model_selection\\_validation.py\", line 895, in _fit_and_score\n    estimator.fit(X_train, y_train, **fit_params)\n  File \"c:\\Users\\Gajalakshmi G\\AppData\\Local\\Programs\\Python\\Python312\\Lib\\site-packages\\sklearn\\base.py\", line 1467, in wrapper\n    estimator._validate_params()\n  File \"c:\\Users\\Gajalakshmi G\\AppData\\Local\\Programs\\Python\\Python312\\Lib\\site-packages\\sklearn\\base.py\", line 666, in _validate_params\n    validate_parameter_constraints(\n  File \"c:\\Users\\Gajalakshmi G\\AppData\\Local\\Programs\\Python\\Python312\\Lib\\site-packages\\sklearn\\utils\\_param_validation.py\", line 95, in validate_parameter_constraints\n    raise InvalidParameterError(\nsklearn.utils._param_validation.InvalidParameterError: The 'criterion' parameter of RandomForestRegressor must be a str among {'squared_error', 'friedman_mse', 'poisson', 'absolute_error'}. Got 'mae' instead.\n\n--------------------------------------------------------------------------------\n4 fits failed with the following error:\nTraceback (most recent call last):\n  File \"c:\\Users\\Gajalakshmi G\\AppData\\Local\\Programs\\Python\\Python312\\Lib\\site-packages\\sklearn\\model_selection\\_validation.py\", line 895, in _fit_and_score\n    estimator.fit(X_train, y_train, **fit_params)\n  File \"c:\\Users\\Gajalakshmi G\\AppData\\Local\\Programs\\Python\\Python312\\Lib\\site-packages\\sklearn\\base.py\", line 1467, in wrapper\n    estimator._validate_params()\n  File \"c:\\Users\\Gajalakshmi G\\AppData\\Local\\Programs\\Python\\Python312\\Lib\\site-packages\\sklearn\\base.py\", line 666, in _validate_params\n    validate_parameter_constraints(\n  File \"c:\\Users\\Gajalakshmi G\\AppData\\Local\\Programs\\Python\\Python312\\Lib\\site-packages\\sklearn\\utils\\_param_validation.py\", line 95, in validate_parameter_constraints\n    raise InvalidParameterError(\nsklearn.utils._param_validation.InvalidParameterError: The 'criterion' parameter of RandomForestRegressor must be a str among {'squared_error', 'friedman_mse', 'absolute_error', 'poisson'}. Got 'mae' instead.\n\n--------------------------------------------------------------------------------\n4 fits failed with the following error:\nTraceback (most recent call last):\n  File \"c:\\Users\\Gajalakshmi G\\AppData\\Local\\Programs\\Python\\Python312\\Lib\\site-packages\\sklearn\\model_selection\\_validation.py\", line 895, in _fit_and_score\n    estimator.fit(X_train, y_train, **fit_params)\n  File \"c:\\Users\\Gajalakshmi G\\AppData\\Local\\Programs\\Python\\Python312\\Lib\\site-packages\\sklearn\\base.py\", line 1467, in wrapper\n    estimator._validate_params()\n  File \"c:\\Users\\Gajalakshmi G\\AppData\\Local\\Programs\\Python\\Python312\\Lib\\site-packages\\sklearn\\base.py\", line 666, in _validate_params\n    validate_parameter_constraints(\n  File \"c:\\Users\\Gajalakshmi G\\AppData\\Local\\Programs\\Python\\Python312\\Lib\\site-packages\\sklearn\\utils\\_param_validation.py\", line 95, in validate_parameter_constraints\n    raise InvalidParameterError(\nsklearn.utils._param_validation.InvalidParameterError: The 'criterion' parameter of RandomForestRegressor must be a str among {'absolute_error', 'squared_error', 'friedman_mse', 'poisson'}. Got 'mae' instead.\n\n--------------------------------------------------------------------------------\n4 fits failed with the following error:\nTraceback (most recent call last):\n  File \"c:\\Users\\Gajalakshmi G\\AppData\\Local\\Programs\\Python\\Python312\\Lib\\site-packages\\sklearn\\model_selection\\_validation.py\", line 895, in _fit_and_score\n    estimator.fit(X_train, y_train, **fit_params)\n  File \"c:\\Users\\Gajalakshmi G\\AppData\\Local\\Programs\\Python\\Python312\\Lib\\site-packages\\sklearn\\base.py\", line 1467, in wrapper\n    estimator._validate_params()\n  File \"c:\\Users\\Gajalakshmi G\\AppData\\Local\\Programs\\Python\\Python312\\Lib\\site-packages\\sklearn\\base.py\", line 666, in _validate_params\n    validate_parameter_constraints(\n  File \"c:\\Users\\Gajalakshmi G\\AppData\\Local\\Programs\\Python\\Python312\\Lib\\site-packages\\sklearn\\utils\\_param_validation.py\", line 95, in validate_parameter_constraints\n    raise InvalidParameterError(\nsklearn.utils._param_validation.InvalidParameterError: The 'criterion' parameter of RandomForestRegressor must be a str among {'squared_error', 'poisson', 'friedman_mse', 'absolute_error'}. Got 'mae' instead.\n\n--------------------------------------------------------------------------------\n3 fits failed with the following error:\nTraceback (most recent call last):\n  File \"c:\\Users\\Gajalakshmi G\\AppData\\Local\\Programs\\Python\\Python312\\Lib\\site-packages\\sklearn\\model_selection\\_validation.py\", line 895, in _fit_and_score\n    estimator.fit(X_train, y_train, **fit_params)\n  File \"c:\\Users\\Gajalakshmi G\\AppData\\Local\\Programs\\Python\\Python312\\Lib\\site-packages\\sklearn\\base.py\", line 1467, in wrapper\n    estimator._validate_params()\n  File \"c:\\Users\\Gajalakshmi G\\AppData\\Local\\Programs\\Python\\Python312\\Lib\\site-packages\\sklearn\\base.py\", line 666, in _validate_params\n    validate_parameter_constraints(\n  File \"c:\\Users\\Gajalakshmi G\\AppData\\Local\\Programs\\Python\\Python312\\Lib\\site-packages\\sklearn\\utils\\_param_validation.py\", line 95, in validate_parameter_constraints\n    raise InvalidParameterError(\nsklearn.utils._param_validation.InvalidParameterError: The 'criterion' parameter of RandomForestRegressor must be a str among {'squared_error', 'poisson', 'absolute_error', 'friedman_mse'}. Got 'mae' instead.\n\n--------------------------------------------------------------------------------\n3 fits failed with the following error:\nTraceback (most recent call last):\n  File \"c:\\Users\\Gajalakshmi G\\AppData\\Local\\Programs\\Python\\Python312\\Lib\\site-packages\\sklearn\\model_selection\\_validation.py\", line 895, in _fit_and_score\n    estimator.fit(X_train, y_train, **fit_params)\n  File \"c:\\Users\\Gajalakshmi G\\AppData\\Local\\Programs\\Python\\Python312\\Lib\\site-packages\\sklearn\\base.py\", line 1467, in wrapper\n    estimator._validate_params()\n  File \"c:\\Users\\Gajalakshmi G\\AppData\\Local\\Programs\\Python\\Python312\\Lib\\site-packages\\sklearn\\base.py\", line 666, in _validate_params\n    validate_parameter_constraints(\n  File \"c:\\Users\\Gajalakshmi G\\AppData\\Local\\Programs\\Python\\Python312\\Lib\\site-packages\\sklearn\\utils\\_param_validation.py\", line 95, in validate_parameter_constraints\n    raise InvalidParameterError(\nsklearn.utils._param_validation.InvalidParameterError: The 'criterion' parameter of RandomForestRegressor must be a str among {'poisson', 'squared_error', 'friedman_mse', 'absolute_error'}. Got 'mae' instead.\n\n--------------------------------------------------------------------------------\n3 fits failed with the following error:\nTraceback (most recent call last):\n  File \"c:\\Users\\Gajalakshmi G\\AppData\\Local\\Programs\\Python\\Python312\\Lib\\site-packages\\sklearn\\model_selection\\_validation.py\", line 895, in _fit_and_score\n    estimator.fit(X_train, y_train, **fit_params)\n  File \"c:\\Users\\Gajalakshmi G\\AppData\\Local\\Programs\\Python\\Python312\\Lib\\site-packages\\sklearn\\base.py\", line 1467, in wrapper\n    estimator._validate_params()\n  File \"c:\\Users\\Gajalakshmi G\\AppData\\Local\\Programs\\Python\\Python312\\Lib\\site-packages\\sklearn\\base.py\", line 666, in _validate_params\n    validate_parameter_constraints(\n  File \"c:\\Users\\Gajalakshmi G\\AppData\\Local\\Programs\\Python\\Python312\\Lib\\site-packages\\sklearn\\utils\\_param_validation.py\", line 95, in validate_parameter_constraints\n    raise InvalidParameterError(\nsklearn.utils._param_validation.InvalidParameterError: The 'criterion' parameter of RandomForestRegressor must be a str among {'poisson', 'absolute_error', 'squared_error', 'friedman_mse'}. Got 'mae' instead.\n",
     "output_type": "error",
     "traceback": [
      "\u001b[1;31m---------------------------------------------------------------------------\u001b[0m",
      "\u001b[1;31mValueError\u001b[0m                                Traceback (most recent call last)",
      "Cell \u001b[1;32mIn[26], line 2\u001b[0m\n\u001b[0;32m      1\u001b[0m grid\u001b[38;5;241m=\u001b[39mGridSearchCV(RandomForestRegressor(), Param_grid, refit\u001b[38;5;241m=\u001b[39m \u001b[38;5;28;01mTrue\u001b[39;00m,verbose\u001b[38;5;241m=\u001b[39m\u001b[38;5;241m3\u001b[39m, n_jobs\u001b[38;5;241m=\u001b[39m\u001b[38;5;241m-\u001b[39m\u001b[38;5;241m1\u001b[39m)\n\u001b[1;32m----> 2\u001b[0m \u001b[43mgrid\u001b[49m\u001b[38;5;241;43m.\u001b[39;49m\u001b[43mfit\u001b[49m\u001b[43m(\u001b[49m\u001b[43mX_train\u001b[49m\u001b[43m,\u001b[49m\u001b[43m \u001b[49m\u001b[43mY_train\u001b[49m\u001b[43m)\u001b[49m\n",
      "File \u001b[1;32mc:\\Users\\Gajalakshmi G\\AppData\\Local\\Programs\\Python\\Python312\\Lib\\site-packages\\sklearn\\base.py:1474\u001b[0m, in \u001b[0;36m_fit_context.<locals>.decorator.<locals>.wrapper\u001b[1;34m(estimator, *args, **kwargs)\u001b[0m\n\u001b[0;32m   1467\u001b[0m     estimator\u001b[38;5;241m.\u001b[39m_validate_params()\n\u001b[0;32m   1469\u001b[0m \u001b[38;5;28;01mwith\u001b[39;00m config_context(\n\u001b[0;32m   1470\u001b[0m     skip_parameter_validation\u001b[38;5;241m=\u001b[39m(\n\u001b[0;32m   1471\u001b[0m         prefer_skip_nested_validation \u001b[38;5;129;01mor\u001b[39;00m global_skip_validation\n\u001b[0;32m   1472\u001b[0m     )\n\u001b[0;32m   1473\u001b[0m ):\n\u001b[1;32m-> 1474\u001b[0m     \u001b[38;5;28;01mreturn\u001b[39;00m \u001b[43mfit_method\u001b[49m\u001b[43m(\u001b[49m\u001b[43mestimator\u001b[49m\u001b[43m,\u001b[49m\u001b[43m \u001b[49m\u001b[38;5;241;43m*\u001b[39;49m\u001b[43margs\u001b[49m\u001b[43m,\u001b[49m\u001b[43m \u001b[49m\u001b[38;5;241;43m*\u001b[39;49m\u001b[38;5;241;43m*\u001b[39;49m\u001b[43mkwargs\u001b[49m\u001b[43m)\u001b[49m\n",
      "File \u001b[1;32mc:\\Users\\Gajalakshmi G\\AppData\\Local\\Programs\\Python\\Python312\\Lib\\site-packages\\sklearn\\model_selection\\_search.py:970\u001b[0m, in \u001b[0;36mBaseSearchCV.fit\u001b[1;34m(self, X, y, **params)\u001b[0m\n\u001b[0;32m    964\u001b[0m     results \u001b[38;5;241m=\u001b[39m \u001b[38;5;28mself\u001b[39m\u001b[38;5;241m.\u001b[39m_format_results(\n\u001b[0;32m    965\u001b[0m         all_candidate_params, n_splits, all_out, all_more_results\n\u001b[0;32m    966\u001b[0m     )\n\u001b[0;32m    968\u001b[0m     \u001b[38;5;28;01mreturn\u001b[39;00m results\n\u001b[1;32m--> 970\u001b[0m \u001b[38;5;28;43mself\u001b[39;49m\u001b[38;5;241;43m.\u001b[39;49m\u001b[43m_run_search\u001b[49m\u001b[43m(\u001b[49m\u001b[43mevaluate_candidates\u001b[49m\u001b[43m)\u001b[49m\n\u001b[0;32m    972\u001b[0m \u001b[38;5;66;03m# multimetric is determined here because in the case of a callable\u001b[39;00m\n\u001b[0;32m    973\u001b[0m \u001b[38;5;66;03m# self.scoring the return type is only known after calling\u001b[39;00m\n\u001b[0;32m    974\u001b[0m first_test_score \u001b[38;5;241m=\u001b[39m all_out[\u001b[38;5;241m0\u001b[39m][\u001b[38;5;124m\"\u001b[39m\u001b[38;5;124mtest_scores\u001b[39m\u001b[38;5;124m\"\u001b[39m]\n",
      "File \u001b[1;32mc:\\Users\\Gajalakshmi G\\AppData\\Local\\Programs\\Python\\Python312\\Lib\\site-packages\\sklearn\\model_selection\\_search.py:1527\u001b[0m, in \u001b[0;36mGridSearchCV._run_search\u001b[1;34m(self, evaluate_candidates)\u001b[0m\n\u001b[0;32m   1525\u001b[0m \u001b[38;5;28;01mdef\u001b[39;00m \u001b[38;5;21m_run_search\u001b[39m(\u001b[38;5;28mself\u001b[39m, evaluate_candidates):\n\u001b[0;32m   1526\u001b[0m \u001b[38;5;250m    \u001b[39m\u001b[38;5;124;03m\"\"\"Search all candidates in param_grid\"\"\"\u001b[39;00m\n\u001b[1;32m-> 1527\u001b[0m     \u001b[43mevaluate_candidates\u001b[49m\u001b[43m(\u001b[49m\u001b[43mParameterGrid\u001b[49m\u001b[43m(\u001b[49m\u001b[38;5;28;43mself\u001b[39;49m\u001b[38;5;241;43m.\u001b[39;49m\u001b[43mparam_grid\u001b[49m\u001b[43m)\u001b[49m\u001b[43m)\u001b[49m\n",
      "File \u001b[1;32mc:\\Users\\Gajalakshmi G\\AppData\\Local\\Programs\\Python\\Python312\\Lib\\site-packages\\sklearn\\model_selection\\_search.py:947\u001b[0m, in \u001b[0;36mBaseSearchCV.fit.<locals>.evaluate_candidates\u001b[1;34m(candidate_params, cv, more_results)\u001b[0m\n\u001b[0;32m    940\u001b[0m \u001b[38;5;28;01melif\u001b[39;00m \u001b[38;5;28mlen\u001b[39m(out) \u001b[38;5;241m!=\u001b[39m n_candidates \u001b[38;5;241m*\u001b[39m n_splits:\n\u001b[0;32m    941\u001b[0m     \u001b[38;5;28;01mraise\u001b[39;00m \u001b[38;5;167;01mValueError\u001b[39;00m(\n\u001b[0;32m    942\u001b[0m         \u001b[38;5;124m\"\u001b[39m\u001b[38;5;124mcv.split and cv.get_n_splits returned \u001b[39m\u001b[38;5;124m\"\u001b[39m\n\u001b[0;32m    943\u001b[0m         \u001b[38;5;124m\"\u001b[39m\u001b[38;5;124minconsistent results. Expected \u001b[39m\u001b[38;5;132;01m{}\u001b[39;00m\u001b[38;5;124m \u001b[39m\u001b[38;5;124m\"\u001b[39m\n\u001b[0;32m    944\u001b[0m         \u001b[38;5;124m\"\u001b[39m\u001b[38;5;124msplits, got \u001b[39m\u001b[38;5;132;01m{}\u001b[39;00m\u001b[38;5;124m\"\u001b[39m\u001b[38;5;241m.\u001b[39mformat(n_splits, \u001b[38;5;28mlen\u001b[39m(out) \u001b[38;5;241m/\u001b[39m\u001b[38;5;241m/\u001b[39m n_candidates)\n\u001b[0;32m    945\u001b[0m     )\n\u001b[1;32m--> 947\u001b[0m \u001b[43m_warn_or_raise_about_fit_failures\u001b[49m\u001b[43m(\u001b[49m\u001b[43mout\u001b[49m\u001b[43m,\u001b[49m\u001b[43m \u001b[49m\u001b[38;5;28;43mself\u001b[39;49m\u001b[38;5;241;43m.\u001b[39;49m\u001b[43merror_score\u001b[49m\u001b[43m)\u001b[49m\n\u001b[0;32m    949\u001b[0m \u001b[38;5;66;03m# For callable self.scoring, the return type is only know after\u001b[39;00m\n\u001b[0;32m    950\u001b[0m \u001b[38;5;66;03m# calling. If the return type is a dictionary, the error scores\u001b[39;00m\n\u001b[0;32m    951\u001b[0m \u001b[38;5;66;03m# can now be inserted with the correct key. The type checking\u001b[39;00m\n\u001b[0;32m    952\u001b[0m \u001b[38;5;66;03m# of out will be done in `_insert_error_scores`.\u001b[39;00m\n\u001b[0;32m    953\u001b[0m \u001b[38;5;28;01mif\u001b[39;00m \u001b[38;5;28mcallable\u001b[39m(\u001b[38;5;28mself\u001b[39m\u001b[38;5;241m.\u001b[39mscoring):\n",
      "File \u001b[1;32mc:\\Users\\Gajalakshmi G\\AppData\\Local\\Programs\\Python\\Python312\\Lib\\site-packages\\sklearn\\model_selection\\_validation.py:536\u001b[0m, in \u001b[0;36m_warn_or_raise_about_fit_failures\u001b[1;34m(results, error_score)\u001b[0m\n\u001b[0;32m    529\u001b[0m \u001b[38;5;28;01mif\u001b[39;00m num_failed_fits \u001b[38;5;241m==\u001b[39m num_fits:\n\u001b[0;32m    530\u001b[0m     all_fits_failed_message \u001b[38;5;241m=\u001b[39m (\n\u001b[0;32m    531\u001b[0m         \u001b[38;5;124mf\u001b[39m\u001b[38;5;124m\"\u001b[39m\u001b[38;5;130;01m\\n\u001b[39;00m\u001b[38;5;124mAll the \u001b[39m\u001b[38;5;132;01m{\u001b[39;00mnum_fits\u001b[38;5;132;01m}\u001b[39;00m\u001b[38;5;124m fits failed.\u001b[39m\u001b[38;5;130;01m\\n\u001b[39;00m\u001b[38;5;124m\"\u001b[39m\n\u001b[0;32m    532\u001b[0m         \u001b[38;5;124m\"\u001b[39m\u001b[38;5;124mIt is very likely that your model is misconfigured.\u001b[39m\u001b[38;5;130;01m\\n\u001b[39;00m\u001b[38;5;124m\"\u001b[39m\n\u001b[0;32m    533\u001b[0m         \u001b[38;5;124m\"\u001b[39m\u001b[38;5;124mYou can try to debug the error by setting error_score=\u001b[39m\u001b[38;5;124m'\u001b[39m\u001b[38;5;124mraise\u001b[39m\u001b[38;5;124m'\u001b[39m\u001b[38;5;124m.\u001b[39m\u001b[38;5;130;01m\\n\u001b[39;00m\u001b[38;5;130;01m\\n\u001b[39;00m\u001b[38;5;124m\"\u001b[39m\n\u001b[0;32m    534\u001b[0m         \u001b[38;5;124mf\u001b[39m\u001b[38;5;124m\"\u001b[39m\u001b[38;5;124mBelow are more details about the failures:\u001b[39m\u001b[38;5;130;01m\\n\u001b[39;00m\u001b[38;5;132;01m{\u001b[39;00mfit_errors_summary\u001b[38;5;132;01m}\u001b[39;00m\u001b[38;5;124m\"\u001b[39m\n\u001b[0;32m    535\u001b[0m     )\n\u001b[1;32m--> 536\u001b[0m     \u001b[38;5;28;01mraise\u001b[39;00m \u001b[38;5;167;01mValueError\u001b[39;00m(all_fits_failed_message)\n\u001b[0;32m    538\u001b[0m \u001b[38;5;28;01melse\u001b[39;00m:\n\u001b[0;32m    539\u001b[0m     some_fits_failed_message \u001b[38;5;241m=\u001b[39m (\n\u001b[0;32m    540\u001b[0m         \u001b[38;5;124mf\u001b[39m\u001b[38;5;124m\"\u001b[39m\u001b[38;5;130;01m\\n\u001b[39;00m\u001b[38;5;132;01m{\u001b[39;00mnum_failed_fits\u001b[38;5;132;01m}\u001b[39;00m\u001b[38;5;124m fits failed out of a total of \u001b[39m\u001b[38;5;132;01m{\u001b[39;00mnum_fits\u001b[38;5;132;01m}\u001b[39;00m\u001b[38;5;124m.\u001b[39m\u001b[38;5;130;01m\\n\u001b[39;00m\u001b[38;5;124m\"\u001b[39m\n\u001b[0;32m    541\u001b[0m         \u001b[38;5;124m\"\u001b[39m\u001b[38;5;124mThe score on these train-test partitions for these parameters\u001b[39m\u001b[38;5;124m\"\u001b[39m\n\u001b[1;32m   (...)\u001b[0m\n\u001b[0;32m    545\u001b[0m         \u001b[38;5;124mf\u001b[39m\u001b[38;5;124m\"\u001b[39m\u001b[38;5;124mBelow are more details about the failures:\u001b[39m\u001b[38;5;130;01m\\n\u001b[39;00m\u001b[38;5;132;01m{\u001b[39;00mfit_errors_summary\u001b[38;5;132;01m}\u001b[39;00m\u001b[38;5;124m\"\u001b[39m\n\u001b[0;32m    546\u001b[0m     )\n",
      "\u001b[1;31mValueError\u001b[0m: \nAll the 60 fits failed.\nIt is very likely that your model is misconfigured.\nYou can try to debug the error by setting error_score='raise'.\n\nBelow are more details about the failures:\n--------------------------------------------------------------------------------\n4 fits failed with the following error:\nTraceback (most recent call last):\n  File \"c:\\Users\\Gajalakshmi G\\AppData\\Local\\Programs\\Python\\Python312\\Lib\\site-packages\\sklearn\\model_selection\\_validation.py\", line 895, in _fit_and_score\n    estimator.fit(X_train, y_train, **fit_params)\n  File \"c:\\Users\\Gajalakshmi G\\AppData\\Local\\Programs\\Python\\Python312\\Lib\\site-packages\\sklearn\\base.py\", line 1467, in wrapper\n    estimator._validate_params()\n  File \"c:\\Users\\Gajalakshmi G\\AppData\\Local\\Programs\\Python\\Python312\\Lib\\site-packages\\sklearn\\base.py\", line 666, in _validate_params\n    validate_parameter_constraints(\n  File \"c:\\Users\\Gajalakshmi G\\AppData\\Local\\Programs\\Python\\Python312\\Lib\\site-packages\\sklearn\\utils\\_param_validation.py\", line 95, in validate_parameter_constraints\n    raise InvalidParameterError(\nsklearn.utils._param_validation.InvalidParameterError: The 'criterion' parameter of RandomForestRegressor must be a str among {'squared_error', 'friedman_mse', 'poisson', 'absolute_error'}. Got 'mse' instead.\n\n--------------------------------------------------------------------------------\n4 fits failed with the following error:\nTraceback (most recent call last):\n  File \"c:\\Users\\Gajalakshmi G\\AppData\\Local\\Programs\\Python\\Python312\\Lib\\site-packages\\sklearn\\model_selection\\_validation.py\", line 895, in _fit_and_score\n    estimator.fit(X_train, y_train, **fit_params)\n  File \"c:\\Users\\Gajalakshmi G\\AppData\\Local\\Programs\\Python\\Python312\\Lib\\site-packages\\sklearn\\base.py\", line 1467, in wrapper\n    estimator._validate_params()\n  File \"c:\\Users\\Gajalakshmi G\\AppData\\Local\\Programs\\Python\\Python312\\Lib\\site-packages\\sklearn\\base.py\", line 666, in _validate_params\n    validate_parameter_constraints(\n  File \"c:\\Users\\Gajalakshmi G\\AppData\\Local\\Programs\\Python\\Python312\\Lib\\site-packages\\sklearn\\utils\\_param_validation.py\", line 95, in validate_parameter_constraints\n    raise InvalidParameterError(\nsklearn.utils._param_validation.InvalidParameterError: The 'criterion' parameter of RandomForestRegressor must be a str among {'squared_error', 'friedman_mse', 'absolute_error', 'poisson'}. Got 'mse' instead.\n\n--------------------------------------------------------------------------------\n4 fits failed with the following error:\nTraceback (most recent call last):\n  File \"c:\\Users\\Gajalakshmi G\\AppData\\Local\\Programs\\Python\\Python312\\Lib\\site-packages\\sklearn\\model_selection\\_validation.py\", line 895, in _fit_and_score\n    estimator.fit(X_train, y_train, **fit_params)\n  File \"c:\\Users\\Gajalakshmi G\\AppData\\Local\\Programs\\Python\\Python312\\Lib\\site-packages\\sklearn\\base.py\", line 1467, in wrapper\n    estimator._validate_params()\n  File \"c:\\Users\\Gajalakshmi G\\AppData\\Local\\Programs\\Python\\Python312\\Lib\\site-packages\\sklearn\\base.py\", line 666, in _validate_params\n    validate_parameter_constraints(\n  File \"c:\\Users\\Gajalakshmi G\\AppData\\Local\\Programs\\Python\\Python312\\Lib\\site-packages\\sklearn\\utils\\_param_validation.py\", line 95, in validate_parameter_constraints\n    raise InvalidParameterError(\nsklearn.utils._param_validation.InvalidParameterError: The 'criterion' parameter of RandomForestRegressor must be a str among {'absolute_error', 'squared_error', 'friedman_mse', 'poisson'}. Got 'mse' instead.\n\n--------------------------------------------------------------------------------\n4 fits failed with the following error:\nTraceback (most recent call last):\n  File \"c:\\Users\\Gajalakshmi G\\AppData\\Local\\Programs\\Python\\Python312\\Lib\\site-packages\\sklearn\\model_selection\\_validation.py\", line 895, in _fit_and_score\n    estimator.fit(X_train, y_train, **fit_params)\n  File \"c:\\Users\\Gajalakshmi G\\AppData\\Local\\Programs\\Python\\Python312\\Lib\\site-packages\\sklearn\\base.py\", line 1467, in wrapper\n    estimator._validate_params()\n  File \"c:\\Users\\Gajalakshmi G\\AppData\\Local\\Programs\\Python\\Python312\\Lib\\site-packages\\sklearn\\base.py\", line 666, in _validate_params\n    validate_parameter_constraints(\n  File \"c:\\Users\\Gajalakshmi G\\AppData\\Local\\Programs\\Python\\Python312\\Lib\\site-packages\\sklearn\\utils\\_param_validation.py\", line 95, in validate_parameter_constraints\n    raise InvalidParameterError(\nsklearn.utils._param_validation.InvalidParameterError: The 'criterion' parameter of RandomForestRegressor must be a str among {'squared_error', 'poisson', 'friedman_mse', 'absolute_error'}. Got 'mse' instead.\n\n--------------------------------------------------------------------------------\n4 fits failed with the following error:\nTraceback (most recent call last):\n  File \"c:\\Users\\Gajalakshmi G\\AppData\\Local\\Programs\\Python\\Python312\\Lib\\site-packages\\sklearn\\model_selection\\_validation.py\", line 895, in _fit_and_score\n    estimator.fit(X_train, y_train, **fit_params)\n  File \"c:\\Users\\Gajalakshmi G\\AppData\\Local\\Programs\\Python\\Python312\\Lib\\site-packages\\sklearn\\base.py\", line 1467, in wrapper\n    estimator._validate_params()\n  File \"c:\\Users\\Gajalakshmi G\\AppData\\Local\\Programs\\Python\\Python312\\Lib\\site-packages\\sklearn\\base.py\", line 666, in _validate_params\n    validate_parameter_constraints(\n  File \"c:\\Users\\Gajalakshmi G\\AppData\\Local\\Programs\\Python\\Python312\\Lib\\site-packages\\sklearn\\utils\\_param_validation.py\", line 95, in validate_parameter_constraints\n    raise InvalidParameterError(\nsklearn.utils._param_validation.InvalidParameterError: The 'criterion' parameter of RandomForestRegressor must be a str among {'squared_error', 'poisson', 'absolute_error', 'friedman_mse'}. Got 'mse' instead.\n\n--------------------------------------------------------------------------------\n4 fits failed with the following error:\nTraceback (most recent call last):\n  File \"c:\\Users\\Gajalakshmi G\\AppData\\Local\\Programs\\Python\\Python312\\Lib\\site-packages\\sklearn\\model_selection\\_validation.py\", line 895, in _fit_and_score\n    estimator.fit(X_train, y_train, **fit_params)\n  File \"c:\\Users\\Gajalakshmi G\\AppData\\Local\\Programs\\Python\\Python312\\Lib\\site-packages\\sklearn\\base.py\", line 1467, in wrapper\n    estimator._validate_params()\n  File \"c:\\Users\\Gajalakshmi G\\AppData\\Local\\Programs\\Python\\Python312\\Lib\\site-packages\\sklearn\\base.py\", line 666, in _validate_params\n    validate_parameter_constraints(\n  File \"c:\\Users\\Gajalakshmi G\\AppData\\Local\\Programs\\Python\\Python312\\Lib\\site-packages\\sklearn\\utils\\_param_validation.py\", line 95, in validate_parameter_constraints\n    raise InvalidParameterError(\nsklearn.utils._param_validation.InvalidParameterError: The 'criterion' parameter of RandomForestRegressor must be a str among {'poisson', 'squared_error', 'friedman_mse', 'absolute_error'}. Got 'mse' instead.\n\n--------------------------------------------------------------------------------\n4 fits failed with the following error:\nTraceback (most recent call last):\n  File \"c:\\Users\\Gajalakshmi G\\AppData\\Local\\Programs\\Python\\Python312\\Lib\\site-packages\\sklearn\\model_selection\\_validation.py\", line 895, in _fit_and_score\n    estimator.fit(X_train, y_train, **fit_params)\n  File \"c:\\Users\\Gajalakshmi G\\AppData\\Local\\Programs\\Python\\Python312\\Lib\\site-packages\\sklearn\\base.py\", line 1467, in wrapper\n    estimator._validate_params()\n  File \"c:\\Users\\Gajalakshmi G\\AppData\\Local\\Programs\\Python\\Python312\\Lib\\site-packages\\sklearn\\base.py\", line 666, in _validate_params\n    validate_parameter_constraints(\n  File \"c:\\Users\\Gajalakshmi G\\AppData\\Local\\Programs\\Python\\Python312\\Lib\\site-packages\\sklearn\\utils\\_param_validation.py\", line 95, in validate_parameter_constraints\n    raise InvalidParameterError(\nsklearn.utils._param_validation.InvalidParameterError: The 'criterion' parameter of RandomForestRegressor must be a str among {'poisson', 'absolute_error', 'squared_error', 'friedman_mse'}. Got 'mse' instead.\n\n--------------------------------------------------------------------------------\n2 fits failed with the following error:\nTraceback (most recent call last):\n  File \"c:\\Users\\Gajalakshmi G\\AppData\\Local\\Programs\\Python\\Python312\\Lib\\site-packages\\sklearn\\model_selection\\_validation.py\", line 895, in _fit_and_score\n    estimator.fit(X_train, y_train, **fit_params)\n  File \"c:\\Users\\Gajalakshmi G\\AppData\\Local\\Programs\\Python\\Python312\\Lib\\site-packages\\sklearn\\base.py\", line 1467, in wrapper\n    estimator._validate_params()\n  File \"c:\\Users\\Gajalakshmi G\\AppData\\Local\\Programs\\Python\\Python312\\Lib\\site-packages\\sklearn\\base.py\", line 666, in _validate_params\n    validate_parameter_constraints(\n  File \"c:\\Users\\Gajalakshmi G\\AppData\\Local\\Programs\\Python\\Python312\\Lib\\site-packages\\sklearn\\utils\\_param_validation.py\", line 95, in validate_parameter_constraints\n    raise InvalidParameterError(\nsklearn.utils._param_validation.InvalidParameterError: The 'criterion' parameter of RandomForestRegressor must be a str among {'poisson', 'absolute_error', 'friedman_mse', 'squared_error'}. Got 'mse' instead.\n\n--------------------------------------------------------------------------------\n5 fits failed with the following error:\nTraceback (most recent call last):\n  File \"c:\\Users\\Gajalakshmi G\\AppData\\Local\\Programs\\Python\\Python312\\Lib\\site-packages\\sklearn\\model_selection\\_validation.py\", line 895, in _fit_and_score\n    estimator.fit(X_train, y_train, **fit_params)\n  File \"c:\\Users\\Gajalakshmi G\\AppData\\Local\\Programs\\Python\\Python312\\Lib\\site-packages\\sklearn\\base.py\", line 1467, in wrapper\n    estimator._validate_params()\n  File \"c:\\Users\\Gajalakshmi G\\AppData\\Local\\Programs\\Python\\Python312\\Lib\\site-packages\\sklearn\\base.py\", line 666, in _validate_params\n    validate_parameter_constraints(\n  File \"c:\\Users\\Gajalakshmi G\\AppData\\Local\\Programs\\Python\\Python312\\Lib\\site-packages\\sklearn\\utils\\_param_validation.py\", line 95, in validate_parameter_constraints\n    raise InvalidParameterError(\nsklearn.utils._param_validation.InvalidParameterError: The 'criterion' parameter of RandomForestRegressor must be a str among {'poisson', 'absolute_error', 'friedman_mse', 'squared_error'}. Got 'mae' instead.\n\n--------------------------------------------------------------------------------\n4 fits failed with the following error:\nTraceback (most recent call last):\n  File \"c:\\Users\\Gajalakshmi G\\AppData\\Local\\Programs\\Python\\Python312\\Lib\\site-packages\\sklearn\\model_selection\\_validation.py\", line 895, in _fit_and_score\n    estimator.fit(X_train, y_train, **fit_params)\n  File \"c:\\Users\\Gajalakshmi G\\AppData\\Local\\Programs\\Python\\Python312\\Lib\\site-packages\\sklearn\\base.py\", line 1467, in wrapper\n    estimator._validate_params()\n  File \"c:\\Users\\Gajalakshmi G\\AppData\\Local\\Programs\\Python\\Python312\\Lib\\site-packages\\sklearn\\base.py\", line 666, in _validate_params\n    validate_parameter_constraints(\n  File \"c:\\Users\\Gajalakshmi G\\AppData\\Local\\Programs\\Python\\Python312\\Lib\\site-packages\\sklearn\\utils\\_param_validation.py\", line 95, in validate_parameter_constraints\n    raise InvalidParameterError(\nsklearn.utils._param_validation.InvalidParameterError: The 'criterion' parameter of RandomForestRegressor must be a str among {'squared_error', 'friedman_mse', 'poisson', 'absolute_error'}. Got 'mae' instead.\n\n--------------------------------------------------------------------------------\n4 fits failed with the following error:\nTraceback (most recent call last):\n  File \"c:\\Users\\Gajalakshmi G\\AppData\\Local\\Programs\\Python\\Python312\\Lib\\site-packages\\sklearn\\model_selection\\_validation.py\", line 895, in _fit_and_score\n    estimator.fit(X_train, y_train, **fit_params)\n  File \"c:\\Users\\Gajalakshmi G\\AppData\\Local\\Programs\\Python\\Python312\\Lib\\site-packages\\sklearn\\base.py\", line 1467, in wrapper\n    estimator._validate_params()\n  File \"c:\\Users\\Gajalakshmi G\\AppData\\Local\\Programs\\Python\\Python312\\Lib\\site-packages\\sklearn\\base.py\", line 666, in _validate_params\n    validate_parameter_constraints(\n  File \"c:\\Users\\Gajalakshmi G\\AppData\\Local\\Programs\\Python\\Python312\\Lib\\site-packages\\sklearn\\utils\\_param_validation.py\", line 95, in validate_parameter_constraints\n    raise InvalidParameterError(\nsklearn.utils._param_validation.InvalidParameterError: The 'criterion' parameter of RandomForestRegressor must be a str among {'squared_error', 'friedman_mse', 'absolute_error', 'poisson'}. Got 'mae' instead.\n\n--------------------------------------------------------------------------------\n4 fits failed with the following error:\nTraceback (most recent call last):\n  File \"c:\\Users\\Gajalakshmi G\\AppData\\Local\\Programs\\Python\\Python312\\Lib\\site-packages\\sklearn\\model_selection\\_validation.py\", line 895, in _fit_and_score\n    estimator.fit(X_train, y_train, **fit_params)\n  File \"c:\\Users\\Gajalakshmi G\\AppData\\Local\\Programs\\Python\\Python312\\Lib\\site-packages\\sklearn\\base.py\", line 1467, in wrapper\n    estimator._validate_params()\n  File \"c:\\Users\\Gajalakshmi G\\AppData\\Local\\Programs\\Python\\Python312\\Lib\\site-packages\\sklearn\\base.py\", line 666, in _validate_params\n    validate_parameter_constraints(\n  File \"c:\\Users\\Gajalakshmi G\\AppData\\Local\\Programs\\Python\\Python312\\Lib\\site-packages\\sklearn\\utils\\_param_validation.py\", line 95, in validate_parameter_constraints\n    raise InvalidParameterError(\nsklearn.utils._param_validation.InvalidParameterError: The 'criterion' parameter of RandomForestRegressor must be a str among {'absolute_error', 'squared_error', 'friedman_mse', 'poisson'}. Got 'mae' instead.\n\n--------------------------------------------------------------------------------\n4 fits failed with the following error:\nTraceback (most recent call last):\n  File \"c:\\Users\\Gajalakshmi G\\AppData\\Local\\Programs\\Python\\Python312\\Lib\\site-packages\\sklearn\\model_selection\\_validation.py\", line 895, in _fit_and_score\n    estimator.fit(X_train, y_train, **fit_params)\n  File \"c:\\Users\\Gajalakshmi G\\AppData\\Local\\Programs\\Python\\Python312\\Lib\\site-packages\\sklearn\\base.py\", line 1467, in wrapper\n    estimator._validate_params()\n  File \"c:\\Users\\Gajalakshmi G\\AppData\\Local\\Programs\\Python\\Python312\\Lib\\site-packages\\sklearn\\base.py\", line 666, in _validate_params\n    validate_parameter_constraints(\n  File \"c:\\Users\\Gajalakshmi G\\AppData\\Local\\Programs\\Python\\Python312\\Lib\\site-packages\\sklearn\\utils\\_param_validation.py\", line 95, in validate_parameter_constraints\n    raise InvalidParameterError(\nsklearn.utils._param_validation.InvalidParameterError: The 'criterion' parameter of RandomForestRegressor must be a str among {'squared_error', 'poisson', 'friedman_mse', 'absolute_error'}. Got 'mae' instead.\n\n--------------------------------------------------------------------------------\n3 fits failed with the following error:\nTraceback (most recent call last):\n  File \"c:\\Users\\Gajalakshmi G\\AppData\\Local\\Programs\\Python\\Python312\\Lib\\site-packages\\sklearn\\model_selection\\_validation.py\", line 895, in _fit_and_score\n    estimator.fit(X_train, y_train, **fit_params)\n  File \"c:\\Users\\Gajalakshmi G\\AppData\\Local\\Programs\\Python\\Python312\\Lib\\site-packages\\sklearn\\base.py\", line 1467, in wrapper\n    estimator._validate_params()\n  File \"c:\\Users\\Gajalakshmi G\\AppData\\Local\\Programs\\Python\\Python312\\Lib\\site-packages\\sklearn\\base.py\", line 666, in _validate_params\n    validate_parameter_constraints(\n  File \"c:\\Users\\Gajalakshmi G\\AppData\\Local\\Programs\\Python\\Python312\\Lib\\site-packages\\sklearn\\utils\\_param_validation.py\", line 95, in validate_parameter_constraints\n    raise InvalidParameterError(\nsklearn.utils._param_validation.InvalidParameterError: The 'criterion' parameter of RandomForestRegressor must be a str among {'squared_error', 'poisson', 'absolute_error', 'friedman_mse'}. Got 'mae' instead.\n\n--------------------------------------------------------------------------------\n3 fits failed with the following error:\nTraceback (most recent call last):\n  File \"c:\\Users\\Gajalakshmi G\\AppData\\Local\\Programs\\Python\\Python312\\Lib\\site-packages\\sklearn\\model_selection\\_validation.py\", line 895, in _fit_and_score\n    estimator.fit(X_train, y_train, **fit_params)\n  File \"c:\\Users\\Gajalakshmi G\\AppData\\Local\\Programs\\Python\\Python312\\Lib\\site-packages\\sklearn\\base.py\", line 1467, in wrapper\n    estimator._validate_params()\n  File \"c:\\Users\\Gajalakshmi G\\AppData\\Local\\Programs\\Python\\Python312\\Lib\\site-packages\\sklearn\\base.py\", line 666, in _validate_params\n    validate_parameter_constraints(\n  File \"c:\\Users\\Gajalakshmi G\\AppData\\Local\\Programs\\Python\\Python312\\Lib\\site-packages\\sklearn\\utils\\_param_validation.py\", line 95, in validate_parameter_constraints\n    raise InvalidParameterError(\nsklearn.utils._param_validation.InvalidParameterError: The 'criterion' parameter of RandomForestRegressor must be a str among {'poisson', 'squared_error', 'friedman_mse', 'absolute_error'}. Got 'mae' instead.\n\n--------------------------------------------------------------------------------\n3 fits failed with the following error:\nTraceback (most recent call last):\n  File \"c:\\Users\\Gajalakshmi G\\AppData\\Local\\Programs\\Python\\Python312\\Lib\\site-packages\\sklearn\\model_selection\\_validation.py\", line 895, in _fit_and_score\n    estimator.fit(X_train, y_train, **fit_params)\n  File \"c:\\Users\\Gajalakshmi G\\AppData\\Local\\Programs\\Python\\Python312\\Lib\\site-packages\\sklearn\\base.py\", line 1467, in wrapper\n    estimator._validate_params()\n  File \"c:\\Users\\Gajalakshmi G\\AppData\\Local\\Programs\\Python\\Python312\\Lib\\site-packages\\sklearn\\base.py\", line 666, in _validate_params\n    validate_parameter_constraints(\n  File \"c:\\Users\\Gajalakshmi G\\AppData\\Local\\Programs\\Python\\Python312\\Lib\\site-packages\\sklearn\\utils\\_param_validation.py\", line 95, in validate_parameter_constraints\n    raise InvalidParameterError(\nsklearn.utils._param_validation.InvalidParameterError: The 'criterion' parameter of RandomForestRegressor must be a str among {'poisson', 'absolute_error', 'squared_error', 'friedman_mse'}. Got 'mae' instead.\n"
     ]
    }
   ],
   "source": [
    "grid=GridSearchCV(RandomForestRegressor(), Param_grid, refit= True,verbose=3, n_jobs=-1)\n",
    "grid.fit(X_train, Y_train)"
   ]
  },
  {
   "cell_type": "code",
   "execution_count": 28,
   "metadata": {},
   "outputs": [
    {
     "ename": "AttributeError",
     "evalue": "'GridSearchCV' object has no attribute 'cv_results_'",
     "output_type": "error",
     "traceback": [
      "\u001b[1;31m---------------------------------------------------------------------------\u001b[0m",
      "\u001b[1;31mAttributeError\u001b[0m                            Traceback (most recent call last)",
      "Cell \u001b[1;32mIn[28], line 1\u001b[0m\n\u001b[1;32m----> 1\u001b[0m re\u001b[38;5;241m=\u001b[39m\u001b[43mgrid\u001b[49m\u001b[38;5;241;43m.\u001b[39;49m\u001b[43mcv_results_\u001b[49m\n\u001b[0;32m      2\u001b[0m grid_predictions \u001b[38;5;241m=\u001b[39m grid\u001b[38;5;241m.\u001b[39mpredict(X_test)\n\u001b[0;32m      3\u001b[0m \u001b[38;5;28;01mfrom\u001b[39;00m \u001b[38;5;21;01msklearn\u001b[39;00m\u001b[38;5;21;01m.\u001b[39;00m\u001b[38;5;21;01mmetrics\u001b[39;00m \u001b[38;5;28;01mimport\u001b[39;00m r2_score\n",
      "\u001b[1;31mAttributeError\u001b[0m: 'GridSearchCV' object has no attribute 'cv_results_'"
     ]
    }
   ],
   "source": [
    "re=grid.cv_results_\n",
    "grid_predictions = grid.predict(X_test)\n",
    "from sklearn.metrics import r2_score\n",
    "r_score=r2_score(y_test,grid_predictions)\n",
    "print(\"The R_score value for best parameter {}:\".format(grid.best_params_),r_score)\n"
   ]
  },
  {
   "cell_type": "code",
   "execution_count": null,
   "metadata": {},
   "outputs": [],
   "source": []
  }
 ],
 "metadata": {
  "kernelspec": {
   "display_name": "Python 3",
   "language": "python",
   "name": "python3"
  },
  "language_info": {
   "codemirror_mode": {
    "name": "ipython",
    "version": 3
   },
   "file_extension": ".py",
   "mimetype": "text/x-python",
   "name": "python",
   "nbconvert_exporter": "python",
   "pygments_lexer": "ipython3",
   "version": "3.12.3"
  }
 },
 "nbformat": 4,
 "nbformat_minor": 2
}
